<?xml version='1.0'?>
<robot name='ateks'>
  
  <!-- Base Footprint -->
    <link name="base_footprint"/> 
    <joint name="base_footprint_joint" type="fixed">     	
	<parent link="base_footprint"/>
     	<child link="base_link"/>	
    </joint> 
    
    
   <!-- Base_Link -->
   
    <link name='base_link'>
    	<inertial>
      	  <mass value="83.7"/>
      	  <origin xyz="0 0 0"/>
      	  <inertia ixx="10.0" ixy="10.0" ixz="10.0" iyy="10.0" iyz="10.0" izz="100.0" />
    	</inertial>
    
    	<visual>
      	  <origin xyz="0.61 0.33 0.1" rpy="0 0.4 3.14"/>
      	    <geometry>
        	<!--<box size ="0.33 0.42 0.05"/>-->
        	    <mesh filename="package://ateks_description/meshes/ateks2.stl" scale="0.001 0.001 0.001"/>
      	    </geometry>
        <!-- <origin xyz="0 0 0.2" rpy="0 0 0" /> -->
        <!-- <geometry> -->
	<!--   <box size="1.1 0.5 0.1"/> -->
        <!-- </geometry> -->
    	</visual>
    	
    	<collision>
      	   <origin rpy="0 0 0" xyz="0 0 0.2"/>
      	    <geometry>
        	    <box size ="1.08 0.6 0.1"/>
      	    </geometry>
    	</collision> 
    	  
     </link>
     
     <gazebo reference="base_link">
    	<material value="Gazebo/DarkGrey "/>
     </gazebo>
     
  <!-- Caster Wheels -->
    <link name='left_caster_wheel'>
    	<collision>
      	   <origin rpy="0 0 0" xyz="0.33884 -0.27 0.075"/>
      	    <geometry>
      	        <sphere radius ="0.075"/>
      	    </geometry>
    	</collision>   
     </link>
     
     <joint name="left_caster_joint" type="fixed">
	      <origin xyz="0 0 0" rpy="0 0 0"/>
	      <parent link="base_link"/>
	      <child link="left_caster_wheel"/>
	      <axis xyz="0 1 0"/>
     </joint> 

    <link name='right_caster_wheel'>
    	<collision>
      	   <origin rpy="0 0 0" xyz="0.33884 0.27 0.075"/>
      	    <geometry>
      	        <sphere radius ="0.075"/>
      	    </geometry>
    	</collision>   
     </link>
     
     <joint name="right_caster_joint" type="fixed">
	      <origin xyz="0 0 0" rpy="0 0 0"/>
	      <parent link="base_link"/>
	      <child link="right_caster_wheel"/>
	      <axis xyz="0 1 0"/>
     </joint>   
     
    <gazebo reference="left_caster_wheel">
      <mu1>0.2</mu1>
      <mu2>0.2</mu2>
    </gazebo>
    <gazebo reference="right_caster_wheel">
      <mu1>0.2</mu1>
      <mu2>0.2</mu2>
    </gazebo>
    
     
  <!-- Back Wheels -->
  
    <link name='left_wheel'>
    	<inertial>
      	  <mass value="1.0"/>
      	  <origin xyz="0.0 0.0 0.0"/>
	  <inertia ixx="1.0" ixy="0" ixz="0" iyy="1.0" iyz="0" izz="1.0" />
    	</inertial>
    
    	<collision>
      	   <origin rpy="1.57 0 0" xyz="0.0 0.0 0.0"/>
      	    <geometry>
      	        <cylinder radius="0.17" length="0.05"/>
      	    </geometry>
    	</collision>   
     </link>
     
     <joint name="left_wheel_joint" type="continuous">
    	<axis xyz="0 1 0"/>
    	<origin xyz="-0.31 0.335 0.17" rpy="0 0 0"/>
    	<parent link="base_link"/>
    	<child link="left_wheel"/>
	<dynamics damping="0.5"/>
     </joint>
     
    <link name='right_wheel'>
    	<inertial>
      	  <mass value="1.0"/>
      	  <origin xyz="0.0 0.0 0.0"/>
	  <inertia ixx="1.0" ixy="0" ixz="0" iyy="1.0" iyz="0" izz="1.0" />
    	</inertial>
    
    	<collision>
      	   <origin rpy="1.57 0 0" xyz="0.0 0.0 0.0"/>
      	    <geometry>
      	        <cylinder radius="0.17" length="0.05"/>
      	    </geometry>
    	</collision>   
     </link>
     
     <joint name="right_wheel_joint" type="continuous">
    	<axis xyz="0 1 0"/>
    	<origin xyz="-0.31 -0.335 0.17" rpy="0 0 0"/>
    	<parent link="base_link"/>
    	<child link="right_wheel"/>
	<dynamics damping="0.5"/>
     </joint>
     

<!-- Camera Port -->
    <link name="kinect_link">
      <pose>0 0 0 0 0 0</pose>
      <inertial>
        <mass value="1.0" />
        <origin xyz="0 0 0" />
        <inertia ixx="1.0" ixy="0" ixz="0" iyy="1.0" iyz="0" izz="1.0" />
      </inertial>

      <visual>
        <origin xyz="0 0 0" rpy="0 0 0" />
        <geometry>
        <mesh filename="package://ateks_description/meshes/kinect.dae" scale="1 1 1"/>
      	  <!-- <sphere radius=".1"/> -->
        </geometry>
		</visual>
	</link>

    <link name="kinect_dummy">
       <pose>0 0 0 0 0 0</pose>
    </link>
	
    <joint name="kinect_joint_dummy" type="fixed">
      <origin xyz="0 0 0" rpy="-1.57 0 -1.57"/>
      <parent link="kinect_link"/>
      <child link="kinect_dummy"/>
      <axis xyz="0 1 0"/>
    </joint>	

    <joint name="kinect_joint" type="fixed">
      <origin xyz="-0.45 -0.2 1.54" rpy="0 0.0 0.0"/> 
      <parent link="base_link"/>
      <child link="kinect_link"/>
      <axis xyz="0 1 0"/>
    </joint>

<!-- Diff Drive Plugin -->
  <gazebo>
    <plugin name="differential_drive_controller" filename="libgazebo_ros_diff_drive.so">
         <alwaysOn>true</alwaysOn>
         <updateRate>10</updateRate>
         <leftJoint>left_wheel_joint</leftJoint>
         <rightJoint>right_wheel_joint</rightJoint>
         <wheelSeparation>0.6</wheelSeparation>
         <wheelDiameter>0.34</wheelDiameter>
         <wheelTorque>20</wheelTorque>
         <!--wheelAcceleration>5</wheelAcceleration-->
         <commandTopic>cmd_vel</commandTopic>
         <publishOdomTF>true</publishOdomTF>
         <odometryTopic>odom</odometryTopic>
         <odometryFrame>odom</odometryFrame>
         <publishTf>1</publishTf>
         <publishWheelJointState>true</publishWheelJointState>
         <robotBaseFrame>base_footprint</robotBaseFrame>
    </plugin>

  </gazebo>
     
<!-- Joint State Publisher 

     <gazebo>
        <plugin name="joint_state_publisher" filename="libgazebo_ros_joint_state_publisher.so">
           <robotNamespace></robotNamespace>
           <jointName>right_wheel_joint, left_wheel_joint</jointName>
           <updateRate>10.0</updateRate>
           <alwaysOn>true</alwaysOn>
        </plugin>
    </gazebo>-->
    
<!-- SENSOR -->
<gazebo reference="kinect_link">
    <sensor type="camera" name="openni_camera_rgb">       
        <always_on>true</always_on>
        <visualize>false</visualize>             
        <camera>
            <horizontal_fov>1.047</horizontal_fov>  
            <image>
                <width>640</width>
                <height>480</height>
                <format>R8G8B8</format>
            </image>
            <clip>
                <near>0.02</near>
                <far>300</far>
            </clip>
        </camera>
        <plugin name="camera_controller" filename="libgazebo_ros_camera.so">
            <alwaysOn>true</alwaysOn>
                <updateRate>2.0</updateRate>
                <cameraName>camera</cameraName>
                <frameName>kinect_dummy</frameName>                   
                <imageTopicName>rgb/image_raw</imageTopicName>
                <cameraInfoTopicName>rgb/camera_info</cameraInfoTopicName>              
                <pointCloudCutoff>0.4</pointCloudCutoff>                
                <hackBaseline>0.07</hackBaseline>
                <distortionK1>0.0</distortionK1>
                <distortionK2>0.0</distortionK2>
                <distortionK3>0.0</distortionK3>
                <distortionT1>0.0</distortionT1>
                <distortionT2>0.0</distortionT2>
                <CxPrime>0.0</CxPrime>
                <Cx>0.0</Cx>
                <Cy>0.0</Cy>
                <focalLength>0.0</focalLength>
            </plugin>
    </sensor>
</gazebo>  

<!-- Laser -->
    <link name="scan_link">
      		
      <collision>
        <origin xyz="0 0 0.0" rpy="0 0 0"/>
        <geometry>
		        <box size ="0.001 0.001 0.001"/>
        </geometry>
      </collision>  
      
    </link>  

    <joint name="scan_joint" type="fixed">
      <origin xyz="0.0 0.0 0.4" rpy="0 0 0"/>
      <parent link="base_link"/>
      <child link="scan_link"/>	 
      <axis xyz="0 0 1"/>    
    </joint>       
    
    <gazebo reference="scan_link">
      <material value="Gazebo/Blue"/>
      <sensor type="ray" name="laser_scan">
        <pose>0 0 0 0 0 0</pose>
        <visualize>false</visualize>
        <update_rate>40</update_rate>
        <ray>
          <scan>
            <horizontal>
              <samples>720</samples>
              <resolution>1</resolution>
              <min_angle>-3.14</min_angle>
              <max_angle>3.14</max_angle>
            </horizontal>
          </scan>
          <range>
            <min>0.10</min>
            <max>30.0</max>
            <resolution>0.03</resolution>
          </range>
          
          <noise>
            <type>gaussian</type>
            <mean>0.0</mean>
            <stddev>0.01</stddev>
          </noise>
        </ray>
        
        <plugin name="laser_scan_plugin" filename="libgazebo_ros_laser.so">
            <topicName>laser</topicName>
            <frameName>scan_link</frameName>
            <tf_prefix>/</tf_prefix>
        </plugin>
      </sensor>
    </gazebo>  


  
<!-- Gazebo ROS Control Plugin -->

  <!--<gazebo>
  	<plugin name="gazebo_ros_control" filename="libgazebo_ros_control.so">
    	<robotNamespace>ateks</robotNamespace>
    	<robotSimType>gazebo_ros_control/DefaultRobotHWSim</robotSimType>
  	</plugin>
  </gazebo>-->

</robot>

